Workbook

Sheet 三人麻雀
A2: 順位 | B2: 名前 | C2: 点数 | D2: 半荘数 | E2: 平均着順 | F2: １着 | G2: ２着 | H2: ３着 | I2: 最高点数 | J2: 最低点数 | K2: 役満回数
A3: 1 | B3: きよ | C3: =SUM(点数表_三麻!B2:B1000) -> 0 | D3: =COUNTIF(点数表_三麻!B2:B1000,"<>0")+2 -> 117 | E3: =(1*F3+2*G3+3*H3)/(F3+G3+H3) -> #DIV/0! | F3: =COUNTIF(点数表_三麻!D2:D1000,"1") -> 0 | G3: =COUNTIF(点数表_三麻!D2:D1000,"2") -> 0 | H3: =COUNTIF(点数表_三麻!D2:D1000,"3") -> 0 | I3: =MAX(点数表_三麻!B2:B1000) -> 0 | J3: =MIN(点数表_三麻!B2:B1000) -> 0
A4: 2 | B4: こたろー | C4: =SUM(点数表_三麻!K2:K1000) -> 0 | D4: =COUNTIF(点数表_三麻!K2:K1000,"<>0") -> 282 | E4: =(1*F4+2*G4+3*H4)/(F4+G4+H4) -> #DIV/0! | F4: =COUNTIF(点数表_三麻!M2:M1000,"1") -> 0 | G4: =COUNTIF(点数表_三麻!M2:M1000,"2") -> 0 | H4: =COUNTIF(点数表_三麻!M2:M1000,"3") -> 0 | I4: =MAX(点数表_三麻!K2:K1000) -> 0 | J4: =MIN(点数表_三麻!K2:K1000) -> 0
A5: 3 | B5: やまだ | C5: =SUM(点数表_三麻!E2:E1000) -> 0 | D5: =COUNTIF(点数表_三麻!E2:E1000,"<>0") -> 228 | E5: =(1*F5+2*G5+3*H5)/(F5+G5+H5) -> #DIV/0! | F5: =COUNTIF(点数表_三麻!G2:G1000,"1") -> 0 | G5: =COUNTIF(点数表_三麻!G2:G1000,"2") -> 0 | H5: =COUNTIF(点数表_三麻!G2:G1000,"3") -> 0 | I5: =MAX(点数表_三麻!E2:E1000) -> 0 | J5: =MIN(点数表_三麻!E2:E1000) -> 0
A6: 4 | B6: よしたに | C6: =SUM(点数表_三麻!H2:H1000) -> 0 | D6: =COUNTIF(点数表_三麻!H2:H1000,"<>0") -> 282 | E6: =(1*F6+2*G6+3*H6)/(F6+G6+H6) -> #DIV/0! | F6: =COUNTIF(点数表_三麻!J2:J1000,"1") -> 0 | G6: =COUNTIF(点数表_三麻!J2:J1000,"2") -> 0 | H6: =COUNTIF(点数表_三麻!J2:J1000,"3") -> 0 | I6: =MAX(点数表_三麻!H2:H1000) -> 0 | J6: =MIN(点数表_三麻!H2:H1000) -> 0
A7: 5 | B7: れい

Sheet 四人麻雀
A2: 順位 | B2: 名前 | C2: 点数 | D2: 半荘数 | E2: 平均着順 | F2: １着 | G2: ２着 | H2: ３着 | I2: ４着 | J2: 最高点数 | K2: 最低点数 | L2: 役満回数
A3: 1 | B3: きよ | C3: =SUM(点数表_四麻!B2:B1000) -> 757.4 | D3: =COUNTIF(点数表_四麻!B2:B1000,"<>0") -> 95 | E3: =(1*F3+2*G3+3*H3+4*I3)/(F3+G3+H3+I3) -> 1.9032258 | F3: =COUNTIF(点数表_四麻!D2:D1000,"1") -> 14 | G3: =COUNTIF(点数表_四麻!D2:D1000,"2") -> 7 | H3: =COUNTIF(点数表_四麻!D2:D1000,"3") -> 9 | I3: =COUNTIF(点数表_四麻!D2:D1000,"4") -> 1 | J3: =MAX(点数表_四麻!B2:B1000) -> 91.5 | K3: =MIN(点数表_四麻!B2:B1000) -> -76.5 | L3: 0
A4: 2 | B4: こたろー | C4: =SUM(点数表_四麻!K2:K1000) -> -477.6 | D4: =COUNTIF(点数表_四麻!K2:K1000,"<>0") -> 95 | E4: =(1*F4+2*G4+3*H4+4*I4)/(F4+G4+H4+I4) -> 2.4137931 | F4: =COUNTIF(点数表_四麻!M2:M1000,"1") -> 9 | G4: =COUNTIF(点数表_四麻!M2:M1000,"2") -> 7 | H4: =COUNTIF(点数表_四麻!M2:M1000,"3") -> 5 | I4: =COUNTIF(点数表_四麻!M2:M1000,"4") -> 8 | J4: =MAX(点数表_四麻!K2:K1000) -> 88.4 | K4: =MIN(点数表_四麻!K2:K1000) -> -68.1 | L4: 0
A5: 3 | B5: やまだ | C5: =SUM(点数表_四麻!E2:E1000) -> 332.7 | D5: =COUNTIF(点数表_四麻!E2:E1000,"<>0") -> 86 | E5: =(1*F5+2*G5+3*H5+4*I5)/(F5+G5+H5+I5) -> 2.6774194 | F5: =COUNTIF(点数表_四麻!G2:G1000,"1") -> 5 | G5: =COUNTIF(点数表_四麻!G2:G1000,"2") -> 10 | H5: =COUNTIF(点数表_四麻!G2:G1000,"3") -> 6 | I5: =COUNTIF(点数表_四麻!G2:G1000,"4") -> 10 | J5: =MAX(点数表_四麻!E2:E1000) -> 93 | K5: =MIN(点数表_四麻!E2:E1000) -> -72.1 | L5: 0
A6: 4 | B6: れい | C6: =SUM(点数表_四麻!N2:N1000) -> -82.2 | D6: =COUNTIF(点数表_四麻!N2:N1000,"<>0") -> 37 | E6: =(1*F6+2*G6+3*H6+4*I6)/(F6+G6+H6+I6) -> 2.8235294 | F6: =COUNTIF(点数表_四麻!P2:P1000,"1") -> 2 | G6: =COUNTIF(点数表_四麻!P2:P1000,"2") -> 5 | H6: =COUNTIF(点数表_四麻!P2:P1000,"3") -> 4 | I6: =COUNTIF(点数表_四麻!P2:P1000,"4") -> 6 | J6: =MAX(点数表_四麻!N2:N1000) -> 83.1 | K6: =MIN(点数表_四麻!N2:N1000) -> -68.3 | L6: 0
A7: 5 | B7: よしたに | C7: =SUM(点数表_四麻!H2:H1000) -> -539.3 | D7: =COUNTIF(点数表_四麻!H2:H1000,"<>0") -> 87 | E7: =(1*F7+2*G7+3*H7+4*I7)/(F7+G7+H7+I7) -> 3.0952381 | F7: =COUNTIF(点数表_四麻!J2:J1000,"1") -> 1 | G7: =COUNTIF(点数表_四麻!J2:J1000,"2") -> 5 | H7: =COUNTIF(点数表_四麻!J2:J1000,"3") -> 6 | I7: =COUNTIF(点数表_四麻!J2:J1000,"4") -> 9 | J7: =MAX(点数表_四麻!H2:H1000) -> 104.3 | K7: =MIN(点数表_四麻!H2:H1000) -> -83.3 | L7: 0

Sheet 点数表_三麻
A1: 日付 | B1: きよ | C1: 合計点数 | E1: やまだ | F1: 合計点数 | G1: 着順 | H1: よしたに | I1: 合計点数 | J1: 着順 | K1: こたろー | L1: 合計点数 | M1: 着順 | N1: れい | O1: 合計点数 | P1: 着順
A2: 45937 | C2: =B2 -> 0 | F2: =E2 -> 0 | I2: =H2 -> 0 | L2: =K2 -> 0 | O2: =N2 -> 0
C3: =C2+B3 -> 0 | F3: =F2+E3 -> 0 | I3: =I2+H3 -> 0 | L3: =L2+K3 -> 0 | O3: =O2+N3 -> 0
C4: =C3+B4 -> 0 | F4: =F3+E4 -> 0 | I4: =I3+H4 -> 0 | L4: =L3+K4 -> 0 | O4: =O3+N4 -> 0
C5: =C4+B5 -> 0 | F5: =F4+E5 -> 0 | I5: =I4+H5 -> 0 | L5: =L4+K5 -> 0 | O5: =O4+N5 -> 0
C6: =C5+B6 -> 0 | F6: =F5+E6 -> 0 | I6: =I5+H6 -> 0 | L6: =L5+K6 -> 0
C7: =C6+B7 -> 0 | F7: =F6+E7 -> 0 | I7: =I6+H7 -> 0 | L7: =L6+K7 -> 0
C8: =C7+B8 -> 0 | F8: =F7+E8 -> 0 | I8: =I7+H8 -> 0 | L8: =L7+K8 -> 0
C9: =C8+B9 -> 0 | F9: =F8+E9 -> 0 | I9: =I8+H9 -> 0 | L9: =L8+K9 -> 0
C10: =C9+B10 -> 0 | F10: =F9+E10 -> 0 | I10: =I9+H10 -> 0 | L10: =L9+K10 -> 0
C11: =C10+B11 -> 0 | F11: =F10+E11 -> 0 | I11: =I10+H11 -> 0 | L11: =L10+K11 -> 0
C12: =C11+B12 -> 0 | F12: =F11+E12 -> 0 | I12: =I11+H12 -> 0 | L12: =L11+K12 -> 0
C13: =C12+B13 -> 0 | F13: =F12+E13 -> 0 | I13: =I12+H13 -> 0 | L13: =L12+K13 -> 0
C14: =C13+B14 -> 0 | F14: =F13+E14 -> 0 | I14: =I13+H14 -> 0 | L14: =L13+K14 -> 0
C15: =C14+B15 -> 0 | F15: =F14+E15 -> 0 | I15: =I14+H15 -> 0 | L15: =L14+K15 -> 0
C16: =C15+B16 -> 0 | F16: =F15+E16 -> 0 | I16: =I15+H16 -> 0 | L16: =L15+K16 -> 0
C17: =C16+B17 -> 0 | F17: =F16+E17 -> 0 | I17: =I16+H17 -> 0 | L17: =L16+K17 -> 0
... C116: =C115+B116 -> 0 | F116: =F115+E116 -> 0 | I116: =I115+H116 -> 0 | L116: =L115+K116 -> 0
B117: 0 | C117: =C116+B117 -> 0 | F117: =F116+E117 -> 0 | I117: =I116+H117 -> 0 | L117: =L116+K117 -> 0
B118: 0 | C118: =C117+B118 -> 0 | F118: =F117+E118 -> 0 | I118: =I117+H118 -> 0 | L118: =L117+K118 -> 0
B119: 0 | C119: =C118+B119 -> 0 | F119: =F118+E119 -> 0 | I119: =I118+H119 -> 0 | L119: =L118+K119 -> 0
B120: 0 | C120: =C119+B120 -> 0 | F120: =F119+E120 -> 0 | I120: =I119+H120 -> 0 | L120: =L119+K120 -> 0
B121: 0 | C121: =C120+B121 -> 0 | F121: =F120+E121 -> 0 | I121: =I120+H121 -> 0 | L121: =L120+K121 -> 0
B122: 0 | C122: =C121+B122 -> 0 | F122: =F121+E122 -> 0 | I122: =I121+H122 -> 0 | L122: =L121+K122 -> 0
B123: 0 | C123: =C122+B123 -> 0 | F123: =F122+E123 -> 0 | I123: =I122+H123 -> 0 | L123: =L122+K123 -> 0
B124: 0 | C124: =C123+B124 -> 0 | F124: =F123+E124 -> 0 | I124: =I123+H124 -> 0 | L124: =L123+K124 -> 0
B125: 0 | C125: =C124+B125 -> 0 | F125: =F124+E125 -> 0 | I125: =I124+H125 -> 0 | L125: =L124+K125 -> 0
B126: 0 | C126: =C125+B126 -> 0 | F126: =F125+E126 -> 0 | I126: =I125+H126 -> 0 | L126: =L125+K126 -> 0
B127: 0 | C127: =C126+B127 -> 0 | F127: =F126+E127 -> 0 | I127: =I126+H127 -> 0 | L127: =L126+K127 -> 0
B128: 0 | C128: =C127+B128 -> 0 | F128: =F127+E128 -> 0 | I128: =I127+H128 -> 0 | L128: =L127+K128 -> 0
... B229: 0 | C229: =C228+B229 -> 0 | F229: =F228+E229 -> 0 | I229: =I228+H229 -> 0 | L229: =L228+K229 -> 0
B230: 0 | C230: =C229+B230 -> 0 | E230: 0 | F230: =F229+E230 -> 0 | I230: =I229+H230 -> 0 | L230: =L229+K230 -> 0
B231: 0 | C231: =C230+B231 -> 0 | E231: 0 | F231: =F230+E231 -> 0 | I231: =I230+H231 -> 0 | L231: =L230+K231 -> 0
B232: 0 | C232: =C231+B232 -> 0 | E232: 0 | F232: =F231+E232 -> 0 | I232: =I231+H232 -> 0 | L232: =L231+K232 -> 0
B233: 0 | C233: =C232+B233 -> 0 | E233: 0 | F233: =F232+E233 -> 0 | I233: =I232+H233 -> 0 | L233: =L232+K233 -> 0
B234: 0 | C234: =C233+B234 -> 0 | E234: 0 | F234: =F233+E234 -> 0 | I234: =I233+H234 -> 0 | L234: =L233+K234 -> 0
B235: 0 | C235: =C234+B235 -> 0 | E235: 0 | F235: =F234+E235 -> 0 | I235: =I234+H235 -> 0 | L235: =L234+K235 -> 0
B236: 0 | C236: =C235+B236 -> 0 | E236: 0 | F236: =F235+E236 -> 0 | I236: =I235+H236 -> 0 | L236: =L235+K236 -> 0
B237: 0 | C237: =C236+B237 -> 0 | E237: 0 | F237: =F236+E237 -> 0 | I237: =I236+H237 -> 0 | L237: =L236+K237 -> 0
B238: 0 | C238: =C237+B238 -> 0 | E238: 0 | F238: =F237+E238 -> 0 | I238: =I237+H238 -> 0 | L238: =L237+K238 -> 0
...

Sheet 点数表_四麻
A1: 日付 | B1: きよ | C1: 合計点数 | D1: 順位 | E1: やまだ | F1: 合計点数 | G1: 順位 | H1: よしたに | I1: 合計点数 | J1: 順位 | K1: こたろー | L1: 合計点数 | M1: 順位 | N1: れい | O1: 合計点数 | P1: 順位 | Q1: ひなた | R1: 合計点数 | S1: 順位 | T1: 全合計
A2: 46057 | B2: 22.3 | C2: =B2 -> 22.3 | D2: 3 | E2: 64.7 | F2: =E2 -> 64.7 | G2: 2 | H2: -70.8 | I2: =H2 -> -70.8 | J2: 0 | K2: -16.2 | L2: =K2 -> -16.2 | M2: 1 | N2: 0 | O2: =N2 -> 0 | P2: 4 | Q2: 0 | R2: =Q2 -> 0 | S2: 0 | T2: =ROUND($B2+$E2+$H2+$K2+$N2+Q2,10) -> 0
B3: -25.4 | C3: =C2+B3 -> -3.1 | D3: 3 | E3: -51.5 | F3: =F2+E3 -> 13.2 | G3: 4 | H3: 76.1 | I3: =I2+H3 -> 5.3 | J3: 0 | K3: 0.8 | L3: =L2+K3 -> -15.4 | M3: 2 | N3: 0 | O3: =O2+N3 -> 0 | P3: 1 | Q3: 0 | R3: =R2+Q3 -> 0 | S3: 0 | T3: =ROUND($B3+$E3+$H3+$K3+$N3+Q3,10) -> 0
B4: 56.9 | C4: =C3+B4 -> 53.8 | D4: 3 | E4: 8.4 | F4: =F3+E4 -> 21.6 | G4: 4 | H4: -13.6 | I4: =I3+H4 -> -8.3 | J4: 0 | K4: -51.7 | L4: =L3+K4 -> -67.1 | M4: 1 | N4: 0 | O4: =O3+N4 -> 0 | P4: 2 | Q4: 0 | R4: =R3+Q4 -> 0 | S4: 0 | T4: =ROUND($B4+$E4+$H4+$K4+$N4+Q4,10) -> 0
B5: 54.3 | C5: =C4+B5 -> 108.1 | D5: 4 | E5: -20 | F5: =F4+E5 -> 1.6 | G5: 2 | H5: -46.9 | I5: =I4+H5 -> -55.2 | J5: 0 | K5: 12.6 | L5: =L4+K5 -> -54.5 | M5: 1 | N5: 0 | O5: =O4+N5 -> 0 | P5: 2 | Q5: 0 | R5: =R4+Q5 -> 0 | S5: 0 | T5: =ROUND($B5+$E5+$H5+$K5+$N5+Q5,10) -> 0
B6: 13.6 | C6: =C5+B6 -> 121.7 | D6: 3 | E6: -51.9 | F6: =F5+E6 -> -50.3 | G6: 1 | H6: -15.8 | I6: =I5+H6 -> -71 | J6: 0 | K6: 54.1 | L6: =L5+K6 -> -0.4 | M6: 4 | N6: 0 | O6: =O5+N6 -> 0 | P6: 2 | Q6: 0 | R6: =R5+Q6 -> 0 | S6: 0 | T6: =ROUND($B6+$E6+$H6+$K6+$N6+Q6,10) -> 0
B7: 65 | C7: =C6+B7 -> 186.7 | D7: 2 | E7: -11.1 | F7: =F6+E7 -> -61.4 | G7: 4 | H7: -78 | I7: =I6+H7 -> -149 | J7: 0 | K7: 24.1 | L7: =L6+K7 -> 23.7 | M7: 3 | N7: 0 | O7: =O6+N7 -> 0 | P7: 1 | Q7: 0 | R7: =R6+Q7 -> 0 | S7: 0 | T7: =ROUND($B7+$E7+$H7+$K7+$N7+Q7,10) -> 0
A8: 46064 | B8: -20.1 | C8: =C7+B8 -> 166.6 | D8: 2 | E8: 10.5 | F8: =F7+E8 -> -50.9 | G8: 3 | H8: 69.6 | I8: =I7+H8 -> -79.4 | J8: 0 | K8: -62 | L8: =L7+K8 -> -38.3 | M8: 1 | N8: 0 | O8: =O7+N8 -> 0 | P8: 4 | Q8: 0 | R8: =R7+Q8 -> 0 | S8: 0 | T8: =ROUND($B8+$E8+$H8+$K8+$N8+Q8,10) -> -2
B9: -43.4 | C9: =C8+B9 -> 123.2 | D9: 2 | E9: 5.6 | F9: =F8+E9 -> -45.3 | G9: 1 | H9: 53.3 | I9: =I8+H9 -> -26.1 | J9: 0 | K9: -15.5 | L9: =L8+K9 -> -53.8 | M9: 4 | N9: 0 | O9: =O8+N9 -> 0 | P9: 3 | Q9: 0 | R9: =R8+Q9 -> 0 | S9: 0 | T9: =ROUND($B9+$E9+$H9+$K9+$N9+Q9,10) -> 0
B10: -21.2 | C10: =C9+B10 -> 102 | D10: 1 | E10: 58.9 | F10: =F9+E10 -> 13.6 | G10: 2 | H10: -53.9 | I10: =I9+H10 -> -80 | J10: 4 | K10: 16.2 | L10: =L9+K10 -> -37.6 | M10: 0 | N10: 0 | O10: =O9+N10 -> 0 | P10: 3 | Q10: 0 | R10: =R9+Q10 -> 0 | S10: 0 | T10: =ROUND($B10+$E10+$H10+$K10+$N10+Q10,10) -> 0
B11: 73.9 | C11: =C10+B11 -> 175.9 | D11: 1 | E11: -51.1 | F11: =F10+E11 -> -37.5 | G11: 2 | H11: -25.9 | I11: =I10+H11 -> -105.9 | J11: 4 | K11: 3.1 | L11: =L10+K11 -> -34.5 | M11: 3 | N11: 0 | O11: =O10+N11 -> 0 | P11: 0 | Q11: 0 | R11: =R10+Q11 -> 0 | S11: 0 | T11: =ROUND($B11+$E11+$H11+$K11+$N11+Q11,10) -> 0
B12: -44.6 | C12: =C11+B12 -> 131.3 | D12: 1 | E12: -20.5 | F12: =F11+E12 -> -58 | G12: 2 | H12: 60.1 | I12: =I11+H12 -> -45.8 | J12: 4 | K12: 5 | L12: =L11+K12 -> -29.5 | M12: 3 | N12: 0 | O12: =O11+N12 -> 0 | P12: 0 | Q12: 0 | R12: =R11+Q12 -> 0 | S12: 0 | T12: =ROUND($B12+$E12+$H12+$K12+$N12+Q12,10) -> 0
B13: -55 | C13: =C12+B13 -> 76.3 | D13: 3 | E13: 2.9 | F13: =F12+E13 -> -55.1 | G13: 4 | H13: 83.4 | I13: =I12+H13 -> 37.6 | J13: 2 | K13: -32.3 | L13: =L12+K13 -> -61.8 | M13: 1 | N13: 0 | O13: =O12+N13 -> 0 | P13: 0 | Q13: 0 | R13: =R12+Q13 -> 0 | S13: 0 | T13: =ROUND($B13+$E13+$H13+$K13+$N13+Q13,10) -> -1
B14: 54.2 | C14: =C13+B14 -> 130.5 | D14: 3 | E14: -17.8 | F14: =F13+E14 -> -72.9 | G14: 1 | H14: -39.6 | I14: =I13+H14 -> -2 | J14: 4 | K14: 3.2 | L14: =L13+K14 -> -58.6 | M14: 2 | N14: 0 | O14: =O13+N14 -> 0 | P14: 0 | Q14: 0 | R14: =R13+Q14 -> 0 | S14: 0 | T14: =ROUND($B14+$E14+$H14+$K14+$N14+Q14,10) -> 0
B15: 54 | C15: =C14+B15 -> 184.5 | D15: 1 | E15: 6.3 | F15: =F14+E15 -> -66.6 | G15: 4 | H15: -45.4 | I15: =I14+H15 -> -47.4 | J15: 3 | K15: -14.9 | L15: =L14+K15 -> -73.5 | M15: 2 | N15: 0 | O15: =O14+N15 -> 0 | P15: 0 | Q15: 0 | R15: =R14+Q15 -> 0 | S15: 0 | T15: =ROUND($B15+$E15+$H15+$K15+$N15+Q15,10) -> 0
B16: -14.8 | C16: =C15+B16 -> 169.7 | D16: 1 | E16: -45.2 | F16: =F15+E16 -> -111.8 | G16: 3 | H16: 7.7 | I16: =I15+H16 -> -39.7 | J16: 2 | K16: 52.3 | L16: =L15+K16 -> -21.2 | M16: 4 | N16: 0 | O16: =O15+N16 -> 0 | P16: 0 | Q16: 0 | R16: =R15+Q16 -> 0 | S16: 0 | T16: =ROUND($B16+$E16+$H16+$K16+$N16+Q16,10) -> 0
A17: 46071 | B17: -25.7 | C17: =C16+B17 -> 144 | D17: 2 | E17: 20.6 | F17: =F16+E17 -> -91.2 | G17: 3 | H17: -83.3 | I17: =I16+H17 -> -123 | J17: 0 | K17: 88.4 | L17: =L16+K17 -> 67.2 | M17: 1 | N17: 0 | O17: =O16+N17 -> 0 | P17: 0 | Q17: 0 | R17: =R16+Q17 -> 0 | S17: 0 | T17: =ROUND($B17+$E17+$H17+$K17+$N17+Q17,10) -> 0
B18: 6.3 | C18: =C17+B18 -> 150.3 | D18: 2 | E18: 63 | F18: =F17+E18 -> -28.2 | G18: 1 | H18: -16.3 | I18: =I17+H18 -> -139.3 | J18: 0 | K18: -53 | L18: =L17+K18 -> 14.2 | M18: 4 | N18: 0 | O18: =O17+N18 -> 0 | P18: 0 | Q18: 0 | R18: =R17+Q18 -> 0 | S18: 0 | T18: =ROUND($B18+$E18+$H18+$K18+$N18+Q18,10) -> 0
B19: -49.9 | C19: =C18+B19 -> 100.4 | D19: 1 | E19: -28.9 | F19: =F18+E19 -> -57.1 | G19: 2 | H19: 11 | I19: =I18+H19 -> -128.3 | J19: 4 | K19: 67.8 | L19: =L18+K19 -> 82 | M19: 0 | N19: 0 | O19: =O18+N19 -> 0 | P19: 0 | Q19: 0 | R19: =R18+Q19 -> 0 | S19: 0 | T19: =ROUND($B19+$E19+$H19+$K19+$N19+Q19,10) -> 0
B20: 2.9 | C20: =C19+B20 -> 103.3 | D20: 1 | E20: -24.1 | F20: =F19+E20 -> -81.2 | G20: 2 | H20: -57.3 | I20: =I19+H20 -> -185.6 | J20: 4 | K20: 78.5 | L20: =L19+K20 -> 160.5 | M20: 3 | N20: 0 | O20: =O19+N20 -> 0 | P20: 0 | Q20: 0 | R20: =R19+Q20 -> 0 | S20: 0 | T20: =ROUND($B20+$E20+$H20+$K20+$N20+Q20,10) -> 0
B21: 3.9 | C21: =C20+B21 -> 107.2 | D21: 1 | E21: -46.4 | F21: =F20+E21 -> -127.6 | G21: 2 | H21: 62.7 | I21: =I20+H21 -> -122.9 | J21: 4 | K21: -20.2 | L21: =L20+K21 -> 140.3 | M21: 3 | N21: 0 | O21: =O20+N21 -> 0 | P21: 0 | Q21: 0 | R21: =R20+Q21 -> 0 | S21: 0 | T21: =ROUND($B21+$E21+$H21+$K21+$N21+Q21,10) -> 0
B22: 10.6 | C22: =C21+B22 -> 117.8 | D22: 3 | E22: 74.9 | F22: =F21+E22 -> -52.7 | G22: 4 | H22: -31 | I22: =I21+H22 -> -153.9 | J22: 2 | K22: -54.5 | L22: =L21+K22 -> 85.8 | M22: 1 | N22: 0 | O22: =O21+N22 -> 0 | P22: 0 | Q22: 0 | R22: =R21+Q22 -> 0 | S22: 0 | T22: =ROUND($B22+$E22+$H22+$K22+$N22+Q22,10) -> 0
B23: -57.9 | C23: =C22+B23 -> 59.9 | D23: 3 | E23: -12.9 | F23: =F22+E23 -> -65.6 | G23: 1 | H23: 104.3 | I23: =I22+H23 -> -49.6 | J23: 4 | K23: -33.5 | L23: =L22+K23 -> 52.3 | M23: 2 | N23: 0 | O23: =O22+N23 -> 0 | P23: 0 | Q23: 0 | R23: =R22+Q23 -> 0 | S23: 0 | T23: =ROUND($B23+$E23+$H23+$K23+$N23+Q23,10) -> 0
A24: 46098 | B24: 75.9 | C24: =C23+B24 -> 135.8 | D24: 1 | E24: 0 | F24: =F23+E24 -> -65.6 | G24: 4 | H24: -79.8 | I24: =I23+H24 -> -129.4 | J24: 3 | K24: -15 | L24: =L23+K24 -> 37.3 | M24: 2 | N24: 18.9 | O24: =O23+N24 -> 18.9 | P24: 0 | Q24: 0 | R24: =R23+Q24 -> 0 | S24: 0 | T24: =ROUND($B24+$E24+$H24+$K24+$N24+Q24,10) -> 0
B25: 52.7 | C25: =C24+B25 -> 188.5 | D25: 1 | E25: 0 | F25: =F24+E25 -> -65.6 | G25: 3 | H25: 11.7 | I25: =I24+H25 -> -117.7 | J25: 2 | K25: -18.6 | L25: =L24+K25 -> 18.7 | M25: 4 | N25: -45.8 | O25: =O24+N25 -> -26.9 | P25: 2 | Q25: 0 | R25: =R24+Q25 -> 0 | S25: 0 | T25: =ROUND($B25+$E25+$H25+$K25+$N25+Q25,10) -> 0
B26: 13.7 | C26: =C25+B26 -> 202.2 | D26: 1 | E26: 0 | F26: =F25+E26 -> -65.6 | G26: 2 | H26: 55.3 | I26: =I25+H26 -> -62.4 | J26: 3 | K26: -18.6 | L26: =L25+K26 -> 0.1 | M26: 4 | N26: -50.4 | O26: =O25+N26 -> -77.3 | P26: 4 | Q26: 0 | R26: =R25+Q26 -> 0 | S26: 0 | T26: =ROUND($B26+$E26+$H26+$K26+$N26+Q26,10) -> 0
B27: 67.7 | C27: =C26+B27 -> 269.9 | D27: 3 | E27: -23.6 | F27: =F26+E27 -> -89.2 | G27: 4 | H27: 0 | I27: =I26+H27 -> -62.4 | J27: 1 | K27: -51 | L27: =L26+K27 -> -50.9 | M27: 2 | N27: 6.9 | O27: =O26+N27 -> -70.4 | P27: 4 | Q27: 0 | R27: =R26+Q27 -> 0 | S27: 0 | T27: =ROUND($B27+$E27+$H27+$K27+$N27+Q27,10) -> 0
B28: 2.6 | C28: =C27+B28 -> 272.5 | D28: 2 | E28: 93 | F28: =F27+E28 -> 3.8 | G28: 3 | H28: -58.7 | I28: =I27+H28 -> -121.1 | J28: 4 | K28: -36.9 | L28: =L27+K28 -> -87.8 | M28: 1 | N28: 0 | O28: =O27+N28 -> -70.4 | P28: 4 | Q28: 0 | R28: =R27+Q28 -> 0 | S28: 0 | T28: =ROUND($B28+$E28+$H28+$K28+$N28+Q28,10) -> 0
B29: -18.8 | C29: =C28+B29 -> 253.7 | D29: 2 | E29: 2.9 | F29: =F28+E29 -> 6.7 | G29: 4 | H29: 59.6 | I29: =I28+H29 -> -61.5 | J29: 3 | K29: 0 | L29: =L28+K29 -> -87.8 | M29: 1 | N29: -43.7 | O29: =O28+N29 -> -114.1 | P29: 3 | Q29: 0 | R29: =R28+Q29 -> 0 | S29: 0 | T29: =ROUND($B29+$E29+$H29+$K29+$N29+Q29,10) -> 0
B30: 0 | C30: =C29+B30 -> 253.7 | D30: 1 | E30: 24.5 | F30: =F29+E30 -> 31.2 | G30: 2 | H30: 68.8 | I30: =I29+H30 -> 7.3 | J30: 3 | K30: -25 | L30: =L29+K30 -> -112.8 | M30: 4 | N30: -68.3 | O30: =O29+N30 -> -182.4 | P30: 2 | Q30: 0 | R30: =R29+Q30 -> 0 | S30: 0 | T30: =ROUND($B30+$E30+$H30+$K30+$N30+Q30,10) -> 0
B31: -40.1 | C31: =C30+B31 -> 213.6 | D31: 1 | E31: 51.2 | F31: =F30+E31 -> 82.4 | G31: 4 | H31: 0 | I31: =I30+H31 -> 7.3 | J31: 3 | K31: -18.3 | L31: =L30+K31 -> -131.1 | M31: 2 | N31: 7.2 | O31: =O30+N31 -> -175.2 | P31: 4 | Q31: 0 | R31: =R30+Q31 -> 0 | S31: 0 | T31: =ROUND($B31+$E31+$H31+$K31+$N31+Q31,10) -> 0
B32: -15.8 | C32: =C31+B32 -> 197.8 | D32: 1 | E32: 6.2 | F32: =F31+E32 -> 88.6 | G32: 3 | H32: -38.4 | I32: =I31+H32 -> -31.1 | J32: 2 | K32: 48 | L32: =L31+K32 -> -83.1 | M32: 4 | N32: 0 | O32: =O31+N32 -> -175.2 | P32: 3 | Q32: 0 | R32: =R31+Q32 -> 0 | S32: 0 | T32: =ROUND($B32+$E32+$H32+$K32+$N32+Q32,10) -> 0
A33: 46113 | B33: -21.3 | C33: =C32+B33 -> 176.5 | E33: 57.6 | F33: =F32+E33 -> 146.2 | H33: 0 | I33: =I32+H33 -> -31.1 | K33: 16.8 | L33: =L32+K33 -> -66.3 | N33: -53.1 | O33: =O32+N33 -> -228.3 | Q33: 0 | R33: =R32+Q33 -> 0 | S33: 0 | T33: =ROUND($B33+$E33+$H33+$K33+$N33+Q33,10) -> 0
B34: -47.9 | C34: =C33+B34 -> 128.6 | E34: -23.4 | F34: =F33+E34 -> 122.8 | H34: 0 | I34: =I33+H34 -> -31.1 | K34: 72.3 | L34: =L33+K34 -> 6 | N34: -1 | O34: =O33+N34 -> -229.3 | Q34: 0 | R34: =R33+Q34 -> 0 | S34: 0 | T34: =ROUND($B34+$E34+$H34+$K34+$N34+Q34,10) -> 0
B35: -44.9 | C35: =C34+B35 -> 83.7 | E35: 61.1 | F35: =F34+E35 -> 183.9 | H35: 0 | I35: =I34+H35 -> -31.1 | K35: 3.9 | L35: =L34+K35 -> 9.9 | N35: -20.1 | O35: =O34+N35 -> -249.4 | Q35: 0 | R35: =R34+Q35 -> 0 | S35: 0 | T35: =ROUND($B35+$E35+$H35+$K35+$N35+Q35,10) -> 0
B36: 5.7 | C36: =C35+B36 -> 89.4 | E36: -45.6 | F36: =F35+E36 -> 138.3 | H36: 0 | I36: =I35+H36 -> -31.1 | K36: 60.5 | L36: =L35+K36 -> 70.4 | N36: -20.6 | O36: =O35+N36 -> -270 | Q36: 0 | R36: =R35+Q36 -> 0 | S36: 0 | T36: =ROUND($B36+$E36+$H36+$K36+$N36+Q36,10) -> 0
B37: -51.1 | C37: =C36+B37 -> 38.3 | E37: 14.4 | F37: =F36+E37 -> 152.7 | H37: 0 | I37: =I36+H37 -> -31.1 | K37: -23.9 | L37: =L36+K37 -> 46.5 | N37: 60.6 | O37: =O36+N37 -> -209.4 | Q37: 0 | R37: =R36+Q37 -> 0 | S37: 0 | T37: =ROUND($B37+$E37+$H37+$K37+$N37+Q37,10) -> 0
B38: 49.9 | C38: =C37+B38 -> 88.2 | E38: 7.9 | F38: =F37+E38 -> 160.6 | H38: 0 | I38: =I37+H38 -> -31.1 | K38: -14.3 | L38: =L37+K38 -> 32.2 | N38: -43.5 | O38: =O37+N38 -> -252.9 | Q38: 0 | R38: =R37+Q38 -> 0 | S38: 0 | T38: =ROUND($B38+$E38+$H38+$K38+$N38+Q38,10) -> 0
A39: 46119 | B39: -54.2 | C39: =C38+B39 -> 34 | E39: 13.3 | F39: =F38+E39 -> 173.9 | H39: 60.6 | I39: =I38+H39 -> 29.5 | K39: -20.7 | L39: =L38+K39 -> 11.5 | N39: 0 | O39: =O38+N39 -> -252.9 | Q39: 0 | R39: =R38+Q39 -> 0 | S39: 0 | T39: =ROUND($B39+$E39+$H39+$K39+$N39+Q39,10) -> -1
B40: -31.1 | C40: =C39+B40 -> 2.9 | E40: -72.1 | F40: =F39+E40 -> 101.8 | H40: 75.7 | I40: =I39+H40 -> 105.2 | K40: 27.5 | L40: =L39+K40 -> 39 | N40: 0 | O40: =O39+N40 -> -252.9 | Q40: 0 | R40: =R39+Q40 -> 0 | S40: 0 | T40: =ROUND($B40+$E40+$H40+$K40+$N40+Q40,10) -> 0
...

Sheet ルール
C3: 四麻 順位点計算方法(素点X) | I3: 三麻 順位点計算方法(素点X)
C4: 順位 | D4: 基準点 | E4: ウマ | F4: ポイント | I4: 順位 | J4: 基準点 | K4: ウマ | L4: ポイント
C5: 1位 | D5: 30,000Pt | E5: 50 | F5: (X－30,000)/1,000+ウマ | I5: 1位 | J5: 25,000Pt | K5: 30 | L5: (X－25,000)/1,000+ウマ
C6: 2位 | E6: 10 | I6: 2位 | K6: 0
C7: 3位 | E7: △ 10 | I7: 3位 | K7: △ 30
C8: 4位 | E8: △ 30
D12: ペナルティ(現状導入なし)
D13: 誤発声 | F13: 1000オール続行or和了放棄
D14: ノーテン立直 | F14: 流局したら4000オール
D15: 誤ロン倒牌 | F15: 4000オール
D16: 少牌多牌 | F16: その牌数のまま和了放棄
